Workbook

Sheet 生成器 Generator
A1: 🚢 报价单生成器 Quotation Generator
A2: 填写黄色格子 → 自动生成报价单 → 切换到「报价单」Sheet 查看 & 发送
A4: 📋 报价单信息 Quote Info
A5: 报价单号 Quote No: | B5: QT-2026-001 | C5: 自定义编号，如 QT-2026-001
A6: 报价日期 Date: | B6: 2026-04-05
A7: 有效期（天）Valid Days: | B7: 7 | C7: 报价单有效期，默认7天
A8: 业务员 Sales: | B8: Brandon
A9: 公司名称 Your Company: | B9: [Your Company] | C9: 你的公司名
A10: 公司电话 Company Phone: | B10: +601x-xxxxxxx
A11: 公司邮箱 Company Email:
A13: 👤 客户信息 Customer Info
A14: 公司名 Company:
A15: 联系人 Contact:
A16: 电话 Phone:
A17: 微信/WhatsApp:
A18: 邮箱 Email:
A20: 📦 货物信息 Shipment Details
A21: 运输方式 Mode: | B21: Sea FCL | C21: Sea FCL / Sea LCL / Air
A22: 起运地 POL: | B22: Shanghai
A23: 目的地 POD: | B23: Port Klang | C23: Port Klang / Kuching / KK / Bintulu / Miri / Sibu
A24: 柜型 Container: | B24: 40HQ | C24: 20GP / 40GP / 40HQ (FCL) 或 CBM/KG
A25: 数量 Quantity: | B25: 1 | C25: 柜数 / CBM / KG
A26: 货品描述 Cargo: | C26: 如: Electronics / Furniture
A27: 货值 Cargo Value (USD): | B27: 0 | C27: 用于计算保险
A29: 💰 费用明细 Cost Breakdown
A30: 在「成本 Cost」列填入你的采购成本，在「报价 Selling」列填入给客户的报价（或留空自动算）
A31: 费用项目 Item | B31: 币种 Ccy | C31: 成本 Cost | D31: 报价 Selling | E31: 自动Margin% | F31: 备注 Notes
A32: 海运费 Ocean Freight | B32: USD | F32: 从供应商拿的运价
A33: THC 码头费 | B33: USD | C33: 150
A34: DOC 文件费 | B34: USD | C34: 50
A35: BAF 燃油附加费 | B35: USD | F35: 按实际或估算
A36: ISPS 安保费 | B36: USD | C36: 15
A37: 报关费 Customs (MYR) | B37: MYR | C37: 200
A38: 本地运费/中转 (MYR) | B38: MYR | F38: 东马转运填这里
A39: 报关费 East MY (MYR) | B39: MYR | C39: 250 | F39: 东马需要
A40: 拖车费 Trucking (MYR) | B40: MYR | F40: 如需送到门
A41: 保险 Insurance | B41: USD | F41: 0.3% cargo value
A42: 其他 Others
A44: 📊 汇总 SUMMARY
A45: 小计 USD Subtotal | E45: Cost | F45: USD 行合计
...

Sheet 报价单 Quotation
A1: =生成器 Generator!B9
A2: Freight Forwarding & Logistics Services
A3: =CONCATENATE("Tel: ",'生成器 Generator'!B10," | Email: ",'生成器 Generator'!B11)
A4: ━━━━━━━━━━━━━━━━━━━━━━━━━━━━━━━━━━━━━━━━━━━━━━━━━━━━━━━━━━━━
A6: QUOTATION | D6: Quote No: | E6: =生成器 Generator!B5
D7: Date: | E7: =生成器 Generator!B6
D8: Valid Until: | E8: =生成器 Generator!B6 + 生成器 Generator!B7
A10: TO:
A11: =生成器 Generator!B14
A12: =CONCATENATE("Attn: ",'生成器 Generator'!B15)
A13: =CONCATENATE("Tel: ",'生成器 Generator'!B16)
A14: =CONCATENATE("Email: ",'生成器 Generator'!B18)
A16: SHIPMENT DETAILS
A17: Service: | B17: =生成器 Generator!B21
A18: Route: | B18: =CONCATENATE(生成器 Generator!B22," → ",生成器 Generator!B23)
A19: Container: | B19: =CONCATENATE(生成器 Generator!B25," x ",生成器 Generator!B24)
A20: Cargo: | B20: =生成器 Generator!B26
A22: COST BREAKDOWN
A23: Item | B23: Currency | C23: Amount | D23: Remarks
A24: Ocean Freight | B24: =IF(生成器 Generator!D32="","",生成器 Generator!D32) | C24: USD
A25: THC | B25: =IF(生成器 Generator!D33="","",生成器 Generator!D33) | C25: USD
A26: Documentation Fee | B26: =IF(生成器 Generator!D34="","",生成器 Generator!D34) | C26: USD
A27: BAF / Fuel Surcharge | B27: =IF(生成器 Generator!D35="","",生成器 Generator!D35) | C27: USD
A28: ISPS | B28: =IF(生成器 Generator!D36="","",生成器 Generator!D36) | C28: USD
A29: Customs Clearance | B29: =IF(生成器 Generator!D37="","",生成器 Generator!D37) | C29: MYR | D29: MY
A30: Local Freight / Transshipment | B30: =IF(生成器 Generator!D38="","",生成器 Generator!D38) | C30: MYR | D30: MY
A31: Customs (East MY) | B31: =IF(生成器 Generator!D39="","",生成器 Generator!D39) | C31: MYR | D31: East MY
A32: Trucking / Delivery | B32: =IF(生成器 Generator!D40="","",生成器 Generator!D40) | C32: MYR
A33: Insurance | B33: =IF(生成器 Generator!D41="","",生成器 Generator!D41) | C33: USD | D33: Optional
A34: Others | B34: =IF(生成器 Generator!D42="","",生成器 Generator!D42)
A36: TOTAL (USD) | B36: =生成器 Generator!C51 | C36: USD
A38: TERMS & CONDITIONS
A39: 1. Quotation valid for 7 days from the date of issue
A40: 2. Rates subject to change without prior notice
A41: 3. Customs inspection fees, storage charges not included
A42: 4. Insurance is optional but strongly recommended
A43: 5. Payment terms: Prepaid / Collect (to be confirmed)
A44: 6. Transit time is estimated and not guaranteed
A47: For any inquiries, please don't hesitate to contact us!
A48: =CONCATENATE(生成器 Generator!B8," | ",生成器 Generator!B10," | ",生成器 Generator!B11)
