Workbook

Sheet 货物信息 Shipment
A1: 📦 货物信息录入 Shipment Information
A2: 填黄色格子 → 切换到其他 Sheet 自动出文档 → 打印/导出 PDF 发给相关方
A4: 📤 发货人 SHIPPER
A5: 公司名 Company:
A6: 地址 Address:
A7: 联系人 Contact:
A8: 电话 Tel:
A9: 邮箱 Email:
A11: 📥 收货人 CONSIGNEE
A12: 公司名 Company:
A13: 地址 Address:
A14: 联系人 Contact:
... A18: 🚢 运输信息 SHIPMENT DETAILS
A19: 运输方式 Mode: | B19: Sea FCL | C19: Sea FCL / Sea LCL / Air
A20: 起运港 POL:
A21: 卸货港 POD:
A22: 最终目的地 Final Dest: | C22: East MY 填这里
A23: 船名/航次 Vessel/Voy: | C23: 确认后填
A24: 提单号 B/L No: | C24: 船公司给的
A25: 订舱号 Booking Ref:
A26: 柜号 Container No: | C26: 装柜后填
A27: 封号 Seal No: | C27: 装柜后填
A28: 截关日 Cut-off Date: | C28: Cutoff date
A29: ETD 预计离港: | C29: Estimated departure
A30: ETA 预计到港: | C30: Estimated arrival
A31: 贸易条款 Incoterms: | B31: FOB | C31: FOB / CIF / EXW / DDP
A32: 付款方式 Payment: | B32: T/T | C32: T/T / L/C / D/P
A34: 📋 货品明细 CARGO ITEMS
A35: 序号 No. | B35: 品名 Description | C35: HS Code | D35: 数量 Qty | E35: 单位 Unit | F35: 净重 KG Net Wt | G35: 毛重 KG Gross Wt | H35: 体积 CBM Meas. | I35: 单价 Unit Price | J35: 总价 Total
A36: 1
A37: 2
A38: 3
A39: 4
A40: 5
A41: 6
A42: 7
A43: 8
A44: 9
A45: 10
A46: 合计 TOTAL
...

Sheet Invoice 发票
A1: COMMERCIAL INVOICE
A3: Invoice No: | B3: =CONCATENATE("INV-",货物信息 Shipment!B25) | D3: Date: | E3: 2026-04-05
D4: B/L No: | E4: =货物信息 Shipment!B24
D5: Booking Ref: | E5: =货物信息 Shipment!B25
A7: SHIPPER / EXPORTER: | D7: CONSIGNEE / IMPORTER:
A8: =货物信息 Shipment!B5 | D8: =货物信息 Shipment!B12
A9: =货物信息 Shipment!B6 | D9: =货物信息 Shipment!B13
A10: =CONCATENATE("Tel: ",货物信息 Shipment!B8) | D10: =CONCATENATE("Tel: ",货物信息 Shipment!B15)
A12: FROM: | B12: =货物信息 Shipment!B20 | D12: TO: | E12: =货物信息 Shipment!B21
A13: VESSEL/VOY: | B13: =货物信息 Shipment!B23 | D13: INCOTERMS: | E13: =货物信息 Shipment!B31
A15: DESCRIPTION OF GOODS
A16: Description | B16: HS Code | C16: Qty | D16: Unit | E16: Gross Wt (KG) | F16: Meas (CBM) | G16: Unit Price | H16: Total
A17: =货物信息 Shipment!B36 | B17: =货物信息 Shipment!C36 | C17: =货物信息 Shipment!D36 | D17: =货物信息 Shipment!E36 | E17: =货物信息 Shipment!G36 | F17: =货物信息 Shipment!H36 | G17: =货物信息 Shipment!I36 | H17: =货物信息 Shipment!J36
A18: =货物信息 Shipment!B37 | B18: =货物信息 Shipment!C37 | C18: =货物信息 Shipment!D37 | D18: =货物信息 Shipment!E37 | E18: =货物信息 Shipment!G37 | F18: =货物信息 Shipment!H37 | G18: =货物信息 Shipment!I37 | H18: =货物信息 Shipment!J37
A19: =货物信息 Shipment!B38 | B19: =货物信息 Shipment!C38 | C19: =货物信息 Shipment!D38 | D19: =货物信息 Shipment!E38 | E19: =货物信息 Shipment!G38 | F19: =货物信息 Shipment!H38 | G19: =货物信息 Shipment!I38 | H19: =货物信息 Shipment!J38
A20: =货物信息 Shipment!B39 | B20: =货物信息 Shipment!C39 | C20: =货物信息 Shipment!D39 | D20: =货物信息 Shipment!E39 | E20: =货物信息 Shipment!G39 | F20: =货物信息 Shipment!H39 | G20: =货物信息 Shipment!I39 | H20: =货物信息 Shipment!J39
A21: =货物信息 Shipment!B40 | B21: =货物信息 Shipment!C40 | C21: =货物信息 Shipment!D40 | D21: =货物信息 Shipment!E40 | E21: =货物信息 Shipment!G40 | F21: =货物信息 Shipment!H40 | G21: =货物信息 Shipment!I40 | H21: =货物信息 Shipment!J40
A22: =货物信息 Shipment!B41 | B22: =货物信息 Shipment!C41 | C22: =货物信息 Shipment!D41 | D22: =货物信息 Shipment!E41 | E22: =货物信息 Shipment!G41 | F22: =货物信息 Shipment!H41 | G22: =货物信息 Shipment!I41 | H22: =货物信息 Shipment!J41
A23: =货物信息 Shipment!B42 | B23: =货物信息 Shipment!C42 | C23: =货物信息 Shipment!D42 | D23: =货物信息 Shipment!E42 | E23: =货物信息 Shipment!G42 | F23: =货物信息 Shipment!H42 | G23: =货物信息 Shipment!I42 | H23: =货物信息 Shipment!J42
A24: =货物信息 Shipment!B43 | B24: =货物信息 Shipment!C43 | C24: =货物信息 Shipment!D43 | D24: =货物信息 Shipment!E43 | E24: =货物信息 Shipment!G43 | F24: =货物信息 Shipment!H43 | G24: =货物信息 Shipment!I43 | H24: =货物信息 Shipment!J43
A25: =货物信息 Shipment!B44 | B25: =货物信息 Shipment!C44 | C25: =货物信息 Shipment!D44 | D25: =货物信息 Shipment!E44 | E25: =货物信息 Shipment!G44 | F25: =货物信息 Shipment!H44 | G25: =货物信息 Shipment!I44 | H25: =货物信息 Shipment!J44
A26: =货物信息 Shipment!B45 | B26: =货物信息 Shipment!C45 | C26: =货物信息 Shipment!D45 | D26: =货物信息 Shipment!E45 | E26: =货物信息 Shipment!G45 | F26: =货物信息 Shipment!H45 | G26: =货物信息 Shipment!I45 | H26: =货物信息 Shipment!J45
A27: TOTAL
A29: TOTAL AMOUNT: | C29: =货物信息 Shipment!B48 | E29: =货物信息 Shipment!J46

Sheet Packing List 装箱单
A1: PACKING LIST
A3: P/L No: | B3: =CONCATENATE("PL-",货物信息 Shipment!B25) | D3: Date: | E3: 2026-04-05
D4: B/L No: | E4: =货物信息 Shipment!B24
A6: SHIPPER: | D6: CONSIGNEE:
A7: =货物信息 Shipment!B5 | D7: =货物信息 Shipment!B12
A8: =货物信息 Shipment!B6 | D8: =货物信息 Shipment!B13
A10: FROM: | B10: =货物信息 Shipment!B20 | D10: TO: | E10: =货物信息 Shipment!B21
A11: CONTAINER: | B11: =货物信息 Shipment!B26 | D11: SEAL: | E11: =货物信息 Shipment!B27
A13: PACKING DETAILS
A14: Description | B14: Qty | C14: Unit | D14: Net Wt (KG) | E14: Gross Wt (KG) | F14: CBM
A15: =货物信息 Shipment!B36 | B15: =货物信息 Shipment!D36 | C15: =货物信息 Shipment!E36 | D15: =货物信息 Shipment!F36 | E15: =货物信息 Shipment!G36 | F15: =货物信息 Shipment!H36
A16: =货物信息 Shipment!B37 | B16: =货物信息 Shipment!D37 | C16: =货物信息 Shipment!E37 | D16: =货物信息 Shipment!F37 | E16: =货物信息 Shipment!G37 | F16: =货物信息 Shipment!H37
A17: =货物信息 Shipment!B38 | B17: =货物信息 Shipment!D38 | C17: =货物信息 Shipment!E38 | D17: =货物信息 Shipment!F38 | E17: =货物信息 Shipment!G38 | F17: =货物信息 Shipment!H38
A18: =货物信息 Shipment!B39 | B18: =货物信息 Shipment!D39 | C18: =货物信息 Shipment!E39 | D18: =货物信息 Shipment!F39 | E18: =货物信息 Shipment!G39 | F18: =货物信息 Shipment!H39
A19: =货物信息 Shipment!B40 | B19: =货物信息 Shipment!D40 | C19: =货物信息 Shipment!E40 | D19: =货物信息 Shipment!F40 | E19: =货物信息 Shipment!G40 | F19: =货物信息 Shipment!H40
A20: =货物信息 Shipment!B41 | B20: =货物信息 Shipment!D41 | C20: =货物信息 Shipment!E41 | D20: =货物信息 Shipment!F41 | E20: =货物信息 Shipment!G41 | F20: =货物信息 Shipment!H41
A21: =货物信息 Shipment!B42 | B21: =货物信息 Shipment!D42 | C21: =货物信息 Shipment!E42 | D21: =货物信息 Shipment!F42 | E21: =货物信息 Shipment!G42 | F21: =货物信息 Shipment!H42
A22: =货物信息 Shipment!B43 | B22: =货物信息 Shipment!D43 | C22: =货物信息 Shipment!E43 | D22: =货物信息 Shipment!F43 | E22: =货物信息 Shipment!G43 | F22: =货物信息 Shipment!H43
A23: =货物信息 Shipment!B44 | B23: =货物信息 Shipment!D44 | C23: =货物信息 Shipment!E44 | D23: =货物信息 Shipment!F44 | E23: =货物信息 Shipment!G44 | F23: =货物信息 Shipment!H44
A24: =货物信息 Shipment!B45 | B24: =货物信息 Shipment!D45 | C24: =货物信息 Shipment!E45 | D24: =货物信息 Shipment!F45 | E24: =货物信息 Shipment!G45 | F24: =货物信息 Shipment!H45
A25: TOTAL

Sheet 文档清单 Checklist
A1: 📋 文档清单 Document Checklist
A3: 订单号 Booking Ref: | B3: =货物信息 Shipment!B25 | D3: 客户: | E3: =货物信息 Shipment!B12
A5: 序号 | B5: 文件 Document | C5: 状态 Status | D5: 负责方 Responsible | E5: 截止日 Deadline | F5: 备注 Notes
A6: 1 | B6: Commercial Invoice 商业发票 | D6: Shipper → You | F6: 必须有
A7: 2 | B7: Packing List 装箱单 | D7: Shipper → You | F7: 必须有
A8: 3 | B8: Bill of Lading (B/L) 提单 | D8: Shipping Line | F8: 船公司出
A9: 4 | B9: Booking Confirmation 订舱确认 | D9: You
A10: 5 | B10: Shipping Order (S/O) 托运单 | D10: You → Shipping Line
A11: 6 | B11: Customs Declaration 报关单 | D11: Customs Broker | F11: 需要报关行
A12: 7 | B12: Certificate of Origin (CO) 原产地证 | D12: Chamber of Commerce | F12: 看客户要求
A13: 8 | B13: Fumigation Certificate 熏蒸证书 | D13: Fumigation Co. | F13: 木质包装需要
A14: 9 | B14: Insurance Certificate 保险单 | D14: Insurance Co. | F14: 如客户要求
A15: 10 | B15: Inspection Report 验货报告 | D15: Inspector | F15: 如需要

Sheet 船期表 Schedule
A1: 🚢 船期跟踪 Shipping Schedule Tracker
A3: 订单号 Booking | B3: 客户 Customer | C3: 航线 Route | D3: 截关日 Cut-off | E3: ETD 离港 | F3: ETA 到港 | G3: 状态 Status
